Workbook

Sheet Data_quality
A1: A (Column Name) | B1: B (Excel Column Letter) | C1: Missing Count | D1: Total Count | E1: Percent Missing | F1: Column1
A2: straatnaam+identificatie_mast A | B2: A | C2: =COUNTBLANK(INDIRECT("'" & "Main_data" & "'!" & B2 & "2:" & B2 & MATCH("zzz", INDIRECT("'" & "Main_data" & "'!" & B2 & ":" & B2), 1))) -> 55338 | D2: =COUNTA(INDIRECT("'" & "Sheet1" & "'!" & B2 & "2:" & B2 & "60000")) -> 1 | E2: =IFERROR(C2 / (C2 + D2), 0) -> 0.99998193
A3: OBJECTID B | B3: B | C3: =COUNTBLANK(INDIRECT("'" & "Main_data" & "'!" & B3 & "2:" & B3 & MATCH("zzz", INDIRECT("'" & "Main_data" & "'!" & B3 & ":" & B3), 1))) -> 0 | D3: =COUNTA(INDIRECT("'" & "Sheet1" & "'!" & B3 & "2:" & B3 & "60000")) -> 1 | E3: =IFERROR(C3 / (C3 + D3), 0) -> 0
A4: STADSDEEL C | B4: C | C4: =COUNTBLANK(INDIRECT("'" & "Main_data" & "'!" & B4 & "2:" & B4 & MATCH("zzz", INDIRECT("'" & "Main_data" & "'!" & B4 & ":" & B4), 1))) -> 55338 | D4: =COUNTA(INDIRECT("'" & "Sheet1" & "'!" & B4 & "2:" & B4 & "60000")) -> 1 | E4: =IFERROR(C4 / (C4 + D4), 0) -> 0.99998193
A5: WIJK D | B5: D | C5: =COUNTBLANK(INDIRECT("'" & "Main_data" & "'!" & B5 & "2:" & B5 & MATCH("zzz", INDIRECT("'" & "Main_data" & "'!" & B5 & ":" & B5), 1))) -> 55338 | D5: =COUNTA(INDIRECT("'" & "Sheet1" & "'!" & B5 & "2:" & B5 & "60000")) -> 1 | E5: =IFERROR(C5 / (C5 + D5), 0) -> 0.99998193
A6: BUURT E | B6: E | C6: =COUNTBLANK(INDIRECT("'" & "Main_data" & "'!" & B6 & "2:" & B6 & MATCH("zzz", INDIRECT("'" & "Main_data" & "'!" & B6 & ":" & B6), 1))) -> 55338 | D6: =COUNTA(INDIRECT("'" & "Sheet1" & "'!" & B6 & "2:" & B6 & "60000")) -> 1 | E6: =IFERROR(C6 / (C6 + D6), 0) -> 0.99998193
A7: STRAATNAAM F | B7: F | C7: =COUNTBLANK(INDIRECT("'" & "Main_data" & "'!" & B7 & "2:" & B7 & MATCH("zzz", INDIRECT("'" & "Main_data" & "'!" & B7 & ":" & B7), 1))) -> 55338 | D7: =COUNTA(INDIRECT("'" & "Sheet1" & "'!" & B7 & "2:" & B7 & "60000")) -> 1 | E7: =IFERROR(C7 / (C7 + D7), 0) -> 0.99998193
A8: WEGVAK G | B8: G | C8: =COUNTBLANK(INDIRECT("'" & "Main_data" & "'!" & B8 & "2:" & B8 & MATCH("zzz", INDIRECT("'" & "Main_data" & "'!" & B8 & ":" & B8), 1))) -> 1 | D8: =COUNTA(INDIRECT("'" & "Sheet1" & "'!" & B8 & "2:" & B8 & "60000")) -> 1 | E8: =IFERROR(C8 / (C8 + D8), 0) -> 0.5
A9: IDENTIFICATIE H | B9: H | C9: =COUNTBLANK(INDIRECT("'" & "Main_data" & "'!" & B9 & "2:" & B9 & MATCH("zzz", INDIRECT("'" & "Main_data" & "'!" & B9 & ":" & B9), 1))) -> 55338 | D9: =COUNTA(INDIRECT("'" & "Sheet1" & "'!" & B9 & "2:" & B9 & "60000")) -> 1 | E9: =IFERROR(C9 / (C9 + D9), 0) -> 0.99998193
A10: LOKATIE I | B10: I | C10: =COUNTBLANK(INDIRECT("'" & "Main_data" & "'!" & B10 & "2:" & B10 & MATCH("zzz", INDIRECT("'" & "Main_data" & "'!" & B10 & ":" & B10), 1))) -> 56469 | D10: =COUNTA(INDIRECT("'" & "Sheet1" & "'!" & B10 & "2:" & B10 & "60000")) -> 1 | E10: =IFERROR(C10 / (C10 + D10), 0) -> 0.99998229
A11: EIGENAAR J | B11: J | C11: =COUNTBLANK(INDIRECT("'" & "Main_data" & "'!" & B11 & "2:" & B11 & MATCH("zzz", INDIRECT("'" & "Main_data" & "'!" & B11 & ":" & B11), 1))) -> 55337 | D11: =COUNTA(INDIRECT("'" & "Sheet1" & "'!" & B11 & "2:" & B11 & "60000")) -> 1 | E11: =IFERROR(C11 / (C11 + D11), 0) -> 0.99998193
A12: X K | B12: K | C12: =COUNTBLANK(INDIRECT("'" & "Main_data" & "'!" & B12 & "2:" & B12 & MATCH("zzz", INDIRECT("'" & "Main_data" & "'!" & B12 & ":" & B12), 1))) -> 0 | D12: =COUNTA(INDIRECT("'" & "Sheet1" & "'!" & B12 & "2:" & B12 & "60000")) -> 1 | E12: =IFERROR(C12 / (C12 + D12), 0) -> 0
A13: Y L | B13: L | C13: =COUNTBLANK(INDIRECT("'" & "Main_data" & "'!" & B13 & "2:" & B13 & MATCH("zzz", INDIRECT("'" & "Main_data" & "'!" & B13 & ":" & B13), 1))) -> 0 | D13: =COUNTA(INDIRECT("'" & "Sheet1" & "'!" & B13 & "2:" & B13 & "60000")) -> 1 | E13: =IFERROR(C13 / (C13 + D13), 0) -> 0
... A45: NEW CK_IN_KELVIN AU | B45: AU | C45: =COUNTBLANK(INDIRECT("'" & "Main_data" & "'!" & B45 & "2:" & B45 & MATCH("zzz", INDIRECT("'" & "Main_data" & "'!" & B45 & ":" & B45), 1))) -> #N/A | D45: =COUNTA(INDIRECT("'" & "Sheet1" & "'!" & B45 & "2:" & B45 & "60000")) -> 1 | E45: =IFERROR(C45 / (C45 + D45), 0) -> 0

Sheet Helper_table
A1: A (Column Name) | B1: B (Excel Column Letter) | C1: Missing Count | D1: Total Count | E1: Percent Missing
A2: WEGVAK G | B2: G | C2: 1 | D2: 0 | E2: 1
A3: LOKATIE I | B3: I | C3: 54747 | D3: 2007 | E3: 0.96463685
A4: DATUM_ONDERHOUD_LAMP P | B4: P | C4: 268 | D4: 56596 | E4: 0.0047129994
A5: SOORT_LAMP Q | B5: Q | C5: 591 | D5: 56273 | E5: 0.010393219
A6: KLEUR_LAMP R | B6: R | C6: 12686 | D6: 44178 | E6: 0.2230937
A7: RA_WAARDE_LAMP U | B7: U | C7: 1 | D7: 5138 | E7: 0.00019459039
A8: SCHAKELSCHEMA_LAMP W | B8: W | C8: 188 | D8: 56676 | E8: 0.0033061339
A9: IDENTIFICATIE_ARMATUUR X | B9: X | C9: 964 | D9: 55900 | E9: 0.016952729
A10: BRANDSTAND_ARMATUUR AC | B10: AC | C10: 15386 | D10: 41478 | E10: 0.27057541
A11: IDENTIFICATIE_DRAGER_MAST AD | B11: AD | C11: 33947 | D11: 3 | E11: 0.99991163
A12: TYPE_DRAGER_MAST AE | B12: AE | C12: 78 | D12: 56786 | E12: 0.0013716939
A13: DATUM_PLAATSING_DRAGER_MAST AF | B13: AF | C13: 78 | D13: 56786 | E13: 0.0013716939
... A19: CK_IN_KELVIN AP | B19: AP | C19: 45876 | D19: 10949 | E19: 0.80732072

Sheet Main_data
A1: straatnaam+identificatie_mast | B1: OBJECTID | C1: STADSDEEL | D1: WIJK | E1: BUURT | F1: STRAATNAAM | G1: WEGVAK | H1: IDENTIFICATIE | I1: LOKATIE | J1: EIGENAAR | K1: X | L1: Y | M1: IDENTIFICATIE_LAMP | N1: TYPE_LAMP | O1: DATUM_PLAATSING_LAMP | P1: DATUM_ONDERHOUD_LAMP | Q1: SOORT_LAMP | R1: KLEUR_LAMP | S1: WATTAGE_LAMP | T1: LUMEN_LAMP | U1: RA_WAARDE_LAMP | V1: FITTING_LAMP | W1: SCHAKELSCHEMA_LAMP | X1: IDENTIFICATIE_ARMATUUR | Y1: TYPE_ARMATUUR | Z1: DATUM_PLAATSING_ARMATUUR | AA1: DATUM_ONDERHOUD_ARMATUUR | AB1: LPH_ARMATUUR | AC1: BRANDSTAND_ARMATUUR | AD1: IDENTIFICATIE_DRAGER_MAST | AE1: TYPE_DRAGER_MAST | AF1: DATUM_PLAATSING_DRAGER_MAST | AG1: DATUM_ONDERHOUD_DRAGER_MAST | AH1: IDENTIFICATIE_DRAGER_UITHOUDER | AI1: TYPE_DRAGER_UITHOUDER | AJ1: DATUM_PLAATSING_DRAGER_UITHOUD | AK1: DATUM_ONDERHOUD_DRAGER_UITHOUD | AL1: geo_shape | AM1: geo_point_2d | AN1: Locat | AO1: TYPE_LAMP.1 | AP1: Column1 | AQ1: CK_IN_KELVIN
A2: Scherpenering 035 | B2: 4935381 | C2: 6 Strijp | D2: 63 Meerhoven | E2: 638 Eindhoven Airport | F2: Scherpenering | H2: 035 | J2: Gemeente Eindhoven | K2: 153049.07 | L2: 384691.93 | M2: 1 | N2: LED94/830 DM11 | O2: 2020-06-08 | P2: 2045-08-19 | Q2: led | R2: wit | S2: 69 | T2: 11900 | V2: LED | W2: in30lux 100% - 19:00 | X2: A | Y2: BGP761 | Z2: 2020-06-08 | AA2: 2040-06-08 | AB2: 600 | AC2: 1 | AE2: ST 8 V-100.N.183 VZ CIL | AF2: 2020-03-18 | AG2: 2060-03-18 | AI2: ST ENKEL 100 X 162 V | AJ2: 2020-03-18 | AK2: 2060-03-18 | AL2: {"coordinates":[5.359133139228652,51.45130801888537],"type":"Point"} | AM2: 51.45130801888537, 5.359133139228652 | AN2: 51.451308255369554, 5.359134469772243 | AO2: LED94/830 DM11 | AP2: 3000 | AQ2: =IF(ISBLANK(AP2), IFERROR(IF(VLOOKUP(AO2, Ellens_additions!$A$2:$B$252, 2, FALSE) = "", "", VLOOKUP(AO2, Ellens_additions!$A$2:$B$252, 2, FALSE)), 0), AP2) -> 3000
A3: Scherpenering 037 | B3: 4935383 | C3: 6 Strijp | D3: 63 Meerhoven | E3: 638 Eindhoven Airport | F3: Scherpenering | H3: 037 | J3: Gemeente Eindhoven | K3: 152954.62 | L3: 384850.77 | M3: 1 | N3: LED94/830 DM11 | O3: 2020-06-08 | P3: 2045-08-19 | Q3: led | R3: wit | S3: 69 | T3: 11900 | V3: LED | W3: in30lux 100% - 19:00 | X3: A | Y3: BGP761 | Z3: 2020-06-08 | AA3: 2040-06-08 | AB3: 600 | AC3: 1 | AE3: ST 8 V-100.N.183 VZ CIL | AF3: 2020-03-18 | AG3: 2060-03-18 | AI3: ST ENKEL 100 X 162 V | AJ3: 2020-03-18 | AK3: 2060-03-18 | AL3: {"coordinates":[5.35777338415337,51.45273546677744],"type":"Point"} | AM3: 51.45273546677744, 5.35777338415337 | AN3: 51.452735700544046, 5.357774715472167 | AO3: LED94/830 DM11 | AP3: 3000 | AQ3: =IF(ISBLANK(AP3), IFERROR(IF(VLOOKUP(AO3, Ellens_additions!$A$2:$B$252, 2, FALSE) = "", "", VLOOKUP(AO3, Ellens_additions!$A$2:$B$252, 2, FALSE)), 0), AP3) -> 3000
A4: Scherpenering 038 | B4: 4935384 | C4: 6 Strijp | D4: 63 Meerhoven | E4: 638 Eindhoven Airport | F4: Scherpenering | H4: 038 | J4: Gemeente Eindhoven | K4: 152907.36 | L4: 384932.69 | M4: 1 | N4: LED94/830 DM50 | O4: 2020-03-18 | P4: 2045-05-12 | Q4: led | S4: 74 | T4: 9400 | V4: LED | W4: in30lux 100% - 19:00 | X4: A | Y4: BGP761 LED94/830 I D | Z4: 2020-03-18 | AA4: 2040-03-18 | AB4: 600 | AC4: 1 | AE4: ST 8 V-100.N.183 VZ CIL | AF4: 2020-03-18 | AG4: 2060-03-18 | AI4: ST ENKEL 100 X 162 V | AJ4: 2020-03-18 | AK4: 2060-03-18 | AL4: {"coordinates":[5.357093014185985,51.45347167426457],"type":"Point"} | AM4: 51.45347167426457, 5.357093014185985 | AN4: 51.45347190666831, 5.357094345581023 | AO4: LED94/830 DM50 | AP4: 3000 | AQ4: =IF(ISBLANK(AP4), IFERROR(IF(VLOOKUP(AO4, [1]Ellens_additions!$A$2:$B$252, 2, FALSE) = "", "", VLOOKUP(AO4, Ellens_additions!$A$2:$B$252, 2, FALSE)), 0), AP4) -> 3000
A5: Mispelhoefstraat 026 | B5: 4935385 | C5: 6 Strijp | D5: 62 Halve Maan | E5: 628 Mispelhoef | F5: Mispelhoefstraat | H5: 026 | J5: Gemeente Eindhoven | K5: 156706.03 | L5: 387037.29 | M5: 1 | N5: SON-T PIA PLUS 50W | O5: 2023-12-01 | P5: 2027-05-17 | Q5: sont | R5: geel | S5: 50 | T5: 4400 | V5: E27 | W5: in30lux 100% - uit30 | X5: A | Y5: SGS203 SON/T 50 W | Z5: 2010-08-31 | AA5: 2040-08-31 | AB5: 900 | AC5: 1 | AE5: ST 9 STANDAARD VZ | AF5: 2001-01-29 | AG5: 2041-01-29 | AI5: ST ENKEL 1 M LOS VZ | AJ5: 2001-01-29 | AK5: 2041-01-29 | AL5: {"coordinates":[5.4117541990350055,51.47239033866345],"type":"Point"} | AM5: 51.47239033866345, 5.4117541990350055 | AN5: 51.472390652893424, 5.4117557166604575 | AO5: SON-T PIA PLUS 50W | AQ5: =IF(ISBLANK(AP5), IFERROR(IF(VLOOKUP(AO5, Ellens_additions!$A$2:$B$252, 2, FALSE) = "", "", VLOOKUP(AO5, Ellens_additions!$A$2:$B$252, 2, FALSE)), 0), AP5) -> 2000
A6: De Schakel 117 | B6: 4935387 | C6: 6 Strijp | D6: 62 Halve Maan | E6: 628 Mispelhoef | F6: De Schakel | H6: 117 | J6: Gemeente Eindhoven | K6: 156655.03 | L6: 387019.37 | M6: 1 | N6: SON PIA PLUS 100W | O6: 2023-11-28 | P6: 2028-12-03 | Q6: son | R6: geel | S6: 100 | T6: 9700 | V6: E40 | W6: in30lux 100% - 19:00 | X6: A | Y6: SGS203 SON 100 W DIM | Z6: 2001-01-29 | AA6: 2031-01-29 | AB6: 900 | AC6: 1 | AE6: ST 9 STANDAARD VZ | AF6: 2001-01-29 | AG6: 2041-01-29 | AI6: ST ENKEL 1 M LOS VZ | AJ6: 2001-01-29 | AK6: 2041-01-29 | AL6: {"coordinates":[5.411020106609674,51.47222938016331],"type":"Point"} | AM6: 51.47222938016331, 5.411020106609674 | AN6: 51.472229693352865, 5.411021622995992 | AO6: SON PIA PLUS 100W | AQ6: =IF(ISBLANK(AP6), IFERROR(IF(VLOOKUP(AO6, Ellens_additions!$A$2:$B$252, 2, FALSE) = "", "", VLOOKUP(AO6, Ellens_additions!$A$2:$B$252, 2, FALSE)), 0), AP6) -> 2000
A7: Botenlaan 023 | B7: 4935397 | C7: 6 Strijp | D7: 61 Oud-Strijp | E7: 614 Schouwbroek | F7: Botenlaan | H7: 023 | J7: Gemeente Eindhoven | K7: 159380.15 | L7: 383386.98 | M7: 1 | N7: LED90/740 I DX50 DGR | O7: 2017-10-09 | P7: 2042-11-16 | Q7: led | R7: wit | S7: 61 | T7: 9000 | V7: LED | W7: in30lux 100% - 19:00 | X7: A | Y7: BGP761 | Z7: 2017-10-16 | AA7: 2037-10-16 | AB7: 900 | AC7: 1 | AE7: ST 11 STANDAARD VZ | AF7: 2001-06-15 | AG7: 2041-06-15 | AI7: ST DUBBEL 1,50 M L. | AJ7: 2001-06-15 | AK7: 2041-06-15 | AL7: {"coordinates":[5.4501972468318565,51.43956443418023],"type":"Point"} | AM7: 51.43956443418023, 5.4501972468318565 | AN7: 51.43956475176129, 5.450198523867777 | AO7: LED90/740 I DX50 DGR | AP7: 4000 | AQ7: =IF(ISBLANK(AP7), IFERROR(IF(VLOOKUP(AO7, Ellens_additions!$A$2:$B$252, 2, FALSE) = "", "", VLOOKUP(AO7, Ellens_additions!$A$2:$B$252, 2, FALSE)), 0), AP7) -> 4000
A8: Lodewijkstraat 002 | B8: 4935399 | C8: 6 Strijp | D8: 62 Halve Maan | E8: 621 Hurk | F8: Lodewijkstraat | H8: 002 | J8: Gemeente Eindhoven | K8: 159471.33 | L8: 382450.38 | M8: 1 | N8: LED239/740 DM70 | O8: 2020-01-15 | P8: 2045-02-20 | Q8: led | S8: 150 | T8: 24000 | V8: LED | W8: in30lux 90% - 19:00 | X8: A | Y8: BGP762 | Z8: 2020-01-15 | AA8: 2040-01-15 | AB8: 1300 | AC8: 1 | AE8: ST 13 V-100.T.114 | AF8: 2001-09-17 | AG8: 2041-09-17 | AI8: ST ENKEL 1,50 M LOS | AJ8: 2001-09-17 | AK8: 2041-09-17 | AL8: {"coordinates":[5.451496743335362,51.431144957595926],"type":"Point"} | AM8: 51.431144957595926, 5.451496743335362 | AN8: 51.431145269255, 5.451497969286229 | AO8: LED239/740 DM70 | AP8: 4000 | AQ8: =IF(ISBLANK(AP8), IFERROR(IF(VLOOKUP(AO8, Ellens_additions!$A$2:$B$252, 2, FALSE) = "", "", VLOOKUP(AO8, Ellens_additions!$A$2:$B$252, 2, FALSE)), 0), AP8) -> 4000
A9: Lodewijkstraat 005 | B9: 4935403 | C9: 6 Strijp | D9: 62 Halve Maan | E9: 621 Hurk | F9: Lodewijkstraat | H9: 005 | J9: Gemeente Eindhoven | K9: 159405.39 | L9: 382588.97 | M9: 1 | N9: LED239/740 DM70 | O9: 2020-01-15 | P9: 2045-02-20 | Q9: led | S9: 150 | T9: 24000 | V9: LED | W9: in30lux 90% - 19:00 | X9: A | Y9: BGP762 | Z9: 2020-01-15 | AA9: 2040-01-15 | AB9: 1300 | AC9: 1 | AE9: ST 13 V-100.T.114 | AF9: 2001-10-03 | AG9: 2041-10-03 | AI9: ST ENKEL 1,50 M LOS | AJ9: 2001-10-03 | AK9: 2041-10-03 | AL9: {"coordinates":[5.450550348425426,51.43239120899901],"type":"Point"} | AM9: 51.43239120899901, 5.450550348425426 | AN9: 51.43239152099905, 5.450551583565537 | AO9: LED239/740 DM70 | AP9: 4000 | AQ9: =IF(ISBLANK(AP9), IFERROR(IF(VLOOKUP(AO9, Ellens_additions!$A$2:$B$252, 2, FALSE) = "", "", VLOOKUP(AO9, Ellens_additions!$A$2:$B$252, 2, FALSE)), 0), AP9) -> 4000
A10: Lodewijkstraat 007 | B10: 4935405 | C10: 6 Strijp | D10: 62 Halve Maan | E10: 621 Hurk | F10: Lodewijkstraat | H10: 007 | J10: Gemeente Eindhoven | K10: 159362.25 | L10: 382684.01 | M10: 1 | N10: LED239/740 DM70 | O10: 2020-01-15 | P10: 2045-02-20 | Q10: led | S10: 150 | T10: 24000 | V10: LED | W10: in30lux 90% - 19:00 | X10: A | Y10: BGP762 | Z10: 2020-01-15 | AA10: 2040-01-15 | AB10: 1300 | AC10: 1 | AE10: ST 13 V-100.T.114 | AF10: 2001-10-03 | AG10: 2041-10-03 | AI10: ST ENKEL 1,50 M LOS | AJ10: 2001-10-03 | AK10: 2041-10-03 | AL10: {"coordinates":[5.449931070233582,51.43324584638235],"type":"Point"} | AM10: 51.43324584638235, 5.449931070233582 | AN10: 51.433246158898505, 5.449932312086022 | AO10: LED239/740 DM70 | AP10: 4000 | AQ10: =IF(ISBLANK(AP10), IFERROR(IF(VLOOKUP(AO10, Ellens_additions!$A$2:$B$252, 2, FALSE) = "", "", VLOOKUP(AO10, Ellens_additions!$A$2:$B$252, 2, FALSE)), 0), AP10) -> 4000
J27: S
A471: Ketelhuisplein 001 | B471: 4936828 | C471: 6 Strijp | D471: 61 Oud-Strijp | E471: 616 Strijp-S | F471: Ketelhuisplein | H471: 001 | J471: Park Strijp beheer | K471: 159844.46 | L471: 384338.06 | M471: 1 | N471: 24 LED LENSOFLEX2 27 | O471: 2014-05-01 | P471: 2039-01-31 | Q471: led | R471: wit | S471: 27 | T471: 3600 | V471: LED | W471: in40lux 100% - uit40 | X471: A | Y471: SCHREDER TECEO-1 AKZ | Z471: 2014-05-01 | AA471: 2034-05-01 | AB471: 60 | AE471: ST 6 CONISCH VZ | AF471: 2014-05-01 | AG471: 2054-05-01 | AI471: ST ENKEL 0,3 M VZ | AJ471: 2014-05-01 | AK471: 2054-05-01 | AL471: {"coordinates":[5.456888237015818,51.44810958797561],"type":"Point"} | AM471: 51.44810958797561, 5.456888237015818 | AN471: 51.44810991489546, 5.456889547046488 | AO471: 24 LED LENSOFLEX2 27 | AQ471: =IF(ISBLANK(AP471), IFERROR(IF(VLOOKUP(AO471, Ellens_additions!$A$2:$B$252, 2, FALSE) = "", "", VLOOKUP(AO471, Ellens_additions!$A$2:$B$252, 2, FALSE)), 0), AP471)
A822: Marathonloop 004 | B822: 4944954 | C822: 5 Woensel-Noord | D822: 51 Ontginning | E822: 511 Driehoeksbos | F822: Marathonloop | H822: 004 | J822: Gemeente Eindhoven | K822: 158896.19 | L822: 387231.88 | N822: LED140-4S/830 DW50 | O822: 2023-11-01 | P822: 2048-12-06 | Q822: led | S822: 106 | T822: 14000 | V822: LED | W822: in30lux 100% - 19:00 | Y822: BGP502 | Z822: 2023-11-01 | AA822: 2043-11-01 | AB822: 0 | AE822: ST 10 V-100.S.210 VZ CIL | AF822: 2023-11-01 | AG822: 2063-11-01 | AI822: ST ENKEL 100x070 | AJ822: 2023-11-01 | AK822: 2053-11-01 | AL822: {"coordinates":[5.443279150581846,51.47412851117845],"type":"Point"} | AM822: 51.47412851117845, 5.443279150581846 | AN822: 51.47412885823664, 5.443280652721446 | AO822: LED140-4S/830 DW50 | AP822: 3000 | AQ822: =IF(ISBLANK(AP822), IFERROR(IF(VLOOKUP(AO822, Ellens_additions!$A$2:$B$252, 2, FALSE) = "", "", VLOOKUP(AO822, Ellens_additions!$A$2:$B$252, 2, FALSE)), 0), AP822) -> 3000
A824: Marathonloop 014 | B824: 4944959 | C824: 5 Woensel-Noord | D824: 51 Ontginning | E824: 511 Driehoeksbos | F824: Marathonloop | H824: 014 | J824: Gemeente Eindhoven | K824: 159037.91 | L824: 387318.83 | N824: LED140-4S/830 DW50 | O824: 2023-11-01 | P824: 2048-12-06 | Q824: led | S824: 106 | T824: 14000 | V824: LED | W824: in30lux 100% - 19:00 | Y824: BGP502 | Z824: 2023-11-01 | AA824: 2043-11-01 | AB824: 0 | AE824: ST 10 V-100.S.210 VZ CIL | AF824: 2023-11-01 | AG824: 2063-11-01 | AI824: ST ENKEL 100x070 | AJ824: 2023-11-01 | AK824: 2053-11-01 | AL824: {"coordinates":[5.44531997698898,51.474909008501484],"type":"Point"} | AM824: 51.474909008501484, 5.44531997698898 | AN824: 51.474909357877586, 5.4453214770018254 | AO824: LED140-4S/830 DW50 | AP824: 3000 | AQ824: =IF(ISBLANK(AP824), IFERROR(IF(VLOOKUP(AO824, Ellens_additions!$A$2:$B$252, 2, FALSE) = "", "", VLOOKUP(AO824, Ellens_additions!$A$2:$B$252, 2, FALSE)), 0), AP824) -> 3000
A826: Marathonloop 016 | B826: 4944960 | C826: 5 Woensel-Noord | D826: 51 Ontginning | E826: 511 Driehoeksbos | F826: Marathonloop | H826: 016 | J826: Gemeente Eindhoven | K826: 159067.45 | L826: 387334.74 | N826: LED140-4S/830 DW50 | O826: 2023-11-01 | P826: 2048-12-06 | Q826: led | S826: 106 | T826: 14000 | V826: LED | W826: in30lux 100% - 19:00 | Y826: BGP502 | Z826: 2023-11-01 | AA826: 2043-11-01 | AB826: 0 | AE826: ST 10 V-100.S.210 VZ CIL | AF826: 2023-11-01 | AG826: 2063-11-01 | AI826: ST ENKEL 100x070 | AJ826: 2023-11-01 | AK826: 2053-11-01 | AL826: {"coordinates":[5.4457453082619995,51.47505184037506],"type":"Point"} | AM826: 51.47505184037506, 5.4457453082619995 | AN826: 51.4750521902145, 5.445746807763235 | AO826: LED140-4S/830 DW50 | AP826: 3000 | AQ826: =IF(ISBLANK(AP826), IFERROR(IF(VLOOKUP(AO826, Ellens_additions!$A$2:$B$252, 2, FALSE) = "", "", VLOOKUP(AO826, Ellens_additions!$A$2:$B$252, 2, FALSE)), 0), AP826) -> 3000
A832: Marathonloop 086 | B832: 4944965 | C832: 5 Woensel-Noord | D832: 51 Ontginning | E832: 511 Driehoeksbos | F832: Marathonloop | H832: 086 | J832: Gemeente Eindhoven | K832: 159667.32 | L832: 387689.11 | N832: LED75-4S/830 DX50 | O832: 2023-11-01 | P832: 2048-12-06 | Q832: led | R832: wit | S832: 59 | T832: 7600 | V832: LED | W832: in30lux 100% - 19:00 | X832: A | Y832: BGP502 | Z832: 2023-11-01 | AA832: 2043-11-01 | AB832: 0 | AE832: ST 10 V-100.S.210 VZ CIL | AF832: 2023-11-01 | AG832: 2063-11-01 | AI832: ST DUBBEL 100x071 | AJ832: 2023-11-01 | AK832: 2053-11-01 | AL832: {"coordinates":[5.454384470403611,51.4782325045135],"type":"Point"} | AM832: 51.4782325045135, 5.454384470403611 | AN832: 51.478232862572284, 5.454385958435121 | AO832: LED75-4S/830 DX50 | AP832: 3000 | AQ832: =IF(ISBLANK(AP832), IFERROR(IF(VLOOKUP(AO832, Ellens_additions!$A$2:$B$252, 2, FALSE) = "", "", VLOOKUP(AO832, Ellens_additions!$A$2:$B$252, 2, FALSE)), 0), AP832) -> 3000
A834: Marathonloop 086 | B834: 4944966 | C834: 5 Woensel-Noord | D834: 51 Ontginning | E834: 511 Driehoeksbos | F834: Marathonloop | H834: 086 | J834: Gemeente Eindhoven | K834: 159667.32 | L834: 387689.11 | N834: LED75-4S/830 DX50 | O834: 2023-11-01 | P834: 2048-12-06 | Q834: led | R834: wit | S834: 59 | T834: 7600 | V834: LED | W834: in30lux 100% - 19:00 | X834: B | Y834: BGP502 | Z834: 2023-11-01 | AA834: 2043-11-01 | AB834: 0 | AE834: ST 10 V-100.S.210 VZ CIL | AF834: 2023-11-01 | AG834: 2063-11-01 | AI834: ST DUBBEL 100x071 | AJ834: 2023-11-01 | AK834: 2053-11-01 | AL834: {"coordinates":[5.454384470403611,51.4782325045135],"type":"Point"} | AM834: 51.4782325045135, 5.454384470403611 | AN834: 51.478232862572284, 5.454385958435121 | AO834: LED75-4S/830 DX50 | AP834: 3000 | AQ834: =IF(ISBLANK(AP834), IFERROR(IF(VLOOKUP(AO834, Ellens_additions!$A$2:$B$252, 2, FALSE) = "", "", VLOOKUP(AO834, Ellens_additions!$A$2:$B$252, 2, FALSE)), 0), AP834) -> 3000
A886: Eindhovenseweg 202 | B886: 4945050 | C886: 5 Woensel-Noord | D886: 54 Dommelbeemd | E886: 545 Esp | F886: Eindhovenseweg | H886: 202 | J886: Gemeente Eindhoven | K886: 162658.19 | L886: 389631.82 | N886: LED34/730 DM10 | O886: 2025-01-27 | P886: 2050-03-06 | S886: 22 | T886: 3300 | V886: LED | W886: in30lux 100% - 19:00 | X886: A | Y886: BGP760 | Z886: 2025-01-27 | AA886: 2050-01-27 | AB886: 0 | AE886: AL 6 NEDAL V.061PT03.6E.000 | AF886: 2025-01-27 | AG886: 2055-01-27 | AI886: AL 0,20 Nedal AU.6.6 | AJ886: 2025-01-27 | AK886: 2055-01-27 | AL886: {"coordinates":[5.49747965256178,51.49566200913625],"type":"Point"} | AM886: 51.49566200913625, 5.49747965256178 | AN886: 51.49566239873169, 5.497481027879047 | AO886: LED34/730 DM10 | AP886: 3000 | AQ886: =IF(ISBLANK(AP886), IFERROR(IF(VLOOKUP(AO886, Ellens_additions!$A$2:$B$252, 2, FALSE) = "", "", VLOOKUP(AO886, Ellens_additions!$A$2:$B$252, 2, FALSE)), 0), AP886) -> 3000
A950: Damocleslaan 006 | B950: 4945142 | C950: 4 Woensel-Zuid | D950: 43 Begijnenbroek | E950: 435 Oude Gracht-Oost | F950: Damocleslaan | H950: 006 | J950: Gemeente Eindhoven | K950: 162737.59 | L950: 386273.8 | M950: 1 | N950: LED35/830 DM70 | O950: 2023-12-01 | P950: 2049-11-09 | Q950: led | S950: 28 | T950: 3400 | V950: LED | W950: in30lux 100% - 19:00 | X950: A | Y950: BGP760 | Z950: 2023-12-01 | AA950: 2048-12-01 | AB950: 0 | AE950: AL 6 NEDAL V.061PT03.6E.000 | AF950: 2023-12-01 | AG950: 2053-12-01 | AI950: AL 0,20 Nedal AU.6.6 | AJ950: 2023-12-01 | AK950: 2053-12-01 | AL950: {"coordinates":[5.498549192393212,51.465476917692456],"type":"Point"} | AM950: 51.465476917692456, 5.498549192393212 | AN950: 51.46547727909817, 5.498550447301647 | AO950: LED35/830 DM70 | AP950: 3000 | AQ950: =IF(ISBLANK(AP950), IFERROR(IF(VLOOKUP(AO950, Ellens_additions!$A$2:$B$252, 2, FALSE) = "", "", VLOOKUP(AO950, Ellens_additions!$A$2:$B$252, 2, FALSE)), 0), AP950) -> 3000
A952: Damocleslaan 008 | B952: 4945144 | C952: 4 Woensel-Zuid | D952: 43 Begijnenbroek | E952: 435 Oude Gracht-Oost | F952: Damocleslaan | H952: 008 | J952: Gemeente Eindhoven | K952: 162776.2 | L952: 386248.45 | M952: 1 | N952: LED35/830 DM70 | O952: 2023-12-01 | P952: 2049-11-09 | Q952: led | S952: 28 | T952: 3400 | V952: LED | W952: in30lux 100% - 19:00 | X952: A | Y952: BGP760 | Z952: 2023-12-01 | AA952: 2048-12-01 | AB952: 0 | AE952: AL 6 NEDAL V.061PT03.6E.000 | AF952: 2023-12-01 | AG952: 2053-12-01 | AI952: AL 0,20 Nedal AU.6.6 | AJ952: 2023-12-01 | AK952: 2053-12-01 | AL952: {"coordinates":[5.499104259437313,51.46524846042459],"type":"Point"} | AM952: 51.46524846042459, 5.499104259437313 | AN952: 51.465248821738825, 5.499105510728663 | AO952: LED35/830 DM70 | AP952: 3000 | AQ952: =IF(ISBLANK(AP952), IFERROR(IF(VLOOKUP(AO952, Ellens_additions!$A$2:$B$252, 2, FALSE) = "", "", VLOOKUP(AO952, Ellens_additions!$A$2:$B$252, 2, FALSE)), 0), AP952) -> 3000
A954: Damocleslaan 011 | B954: 4945146 | C954: 4 Woensel-Zuid | D954: 43 Begijnenbroek | E954: 435 Oude Gracht-Oost | F954: Damocleslaan | H954: 011 | J954: Gemeente Eindhoven | K954: 162812.14 | L954: 386225.29 | M954: 1 | N954: LED35/830 DM70 | O954: 2023-12-01 | P954: 2049-11-09 | Q954: led | S954: 28 | T954: 3400 | V954: LED | W954: in30lux 100% - 19:00 | X954: A | Y954: BGP760 | Z954: 2023-12-01 | AA954: 2048-12-01 | AB954: 0 | AE954: AL 6 NEDAL V.061PT03.6E.000 | AF954: 2023-12-01 | AG954: 2053-12-01 | AI954: AL 0,20 Nedal AU.6.6 | AJ954: 2023-12-01 | AK954: 2053-12-01 | AL954: {"coordinates":[5.4996210042828135,51.46503978557335],"type":"Point"} | AM954: 51.46503978557335, 5.4996210042828135 | AN954: 51.465040146813465, 5.499622252228409 | AO954: LED35/830 DM70 | AP954: 3000 | AQ954: =IF(ISBLANK(AP954), IFERROR(IF(VLOOKUP(AO954, Ellens_additions!$A$2:$B$252, 2, FALSE) = "", "", VLOOKUP(AO954, Ellens_additions!$A$2:$B$252, 2, FALSE)), 0), AP954) -> 3000
A1303: Pixelhof 023 | B1303: 4938488 | C1303: 6 Strijp | D1303: 62 Halve Maan | E1303: 625 Zwaanstraat | F1303: Pixelhof | H1303: 023 | J1303: Gemeente Eindhoven | K1303: 159043.8 | L1303: 384616.92 | M1303: 1 | N1303: GRN10/830 PSDD I DW | O1303: 2019-01-01 | P1303: 2031-08-19 | Q1303: led | S1303: 6.8 | T1303: 800 | V1303: LED | W1303: in30lux 100% - uit30 | X1303: A | Y1303: BDS491 | Z1303: 2019-01-01 | AA1303: 2039-01-01 | AB1303: 0 | AE1303: BB IN/OP/AAN WAND/GEVEL | AF1303: 2019-01-01 | AG1303: 2049-01-01 | AI1303: ZRP450 MBW (Wall Mou | AJ1303: 2019-01-01 | AK1303: 2049-01-01 | AL1303: {"coordinates":[5.445373758794369,51.45062246935221],"type":"Point"} | AM1303: 51.45062246935221, 5.445373758794369 | AN1303: 51.45062279462024, 5.445375118566319 | AO1303: GRN10/830 PSDD I DW | AP1303: 3000 | AQ1303: =IF(ISBLANK(AP1303), IFERROR(IF(VLOOKUP(AO1303, Ellens_additions!$A$2:$B$252, 2, FALSE) = "", "", VLOOKUP(AO1303, Ellens_additions!$A$2:$B$252, 2, FALSE)), 0), AP1303) -> 3000
A1307: Pixelhof 021 | B1307: 4938492 | C1307: 6 Strijp | D1307: 62 Halve Maan | E1307: 625 Zwaanstraat | F1307: Pixelhof | H1307: 021 | J1307: Gemeente Eindhoven | K1307: 159065.33 | L1307: 384627.77 | M1307: 1 | N1307: GRN10/830 PSDD I DW | O1307: 2019-01-01 | P1307: 2031-08-19 | Q1307: led | S1307: 6.8 | T1307: 800 | V1307: LED | W1307: in30lux 100% - uit30 | X1307: A | Y1307: BDS491 | Z1307: 2019-01-01 | AA1307: 2039-01-01 | AB1307: 0 | AE1307: BB IN/OP/AAN WAND/GEVEL | AF1307: 2019-01-01 | AG1307: 2049-01-01 | AI1307: ZRP450 MBW (Wall Mou | AJ1307: 2019-01-01 | AK1307: 2049-01-01 | AL1307: {"coordinates":[5.445683615329678,51.450719840875855],"type":"Point"} | AM1307: 51.450719840875855, 5.445683615329678 | AN1307: 51.450720166376556, 5.445684974925803 | AO1307: GRN10/830 PSDD I DW | AP1307: 3000 | AQ1307: =IF(ISBLANK(AP1307), IFERROR(IF(VLOOKUP(AO1307, Ellens_additions!$A$2:$B$252, 2, FALSE) = "", "", VLOOKUP(AO1307, Ellens_additions!$A$2:$B$252, 2, FALSE)), 0), AP1307) -> 3000
A1317: Achtseweg Noord 225 | B1317: 4938505 | C1317: 6 Strijp | D1317: 62 Halve Maan | E1317: 628 Mispelhoef | F1317: Achtseweg Noord | H1317: 225 | J1317: Gemeente Eindhoven | K1317: 157206.09 | L1317: 386956.07 | N1317: LED6-4S/830 DM11 | O1317: 2024-03-01 | P1317: 2049-04-18 | S1317: 6.9 | T1317: 600 | V1317: LED | W1317: in30lux 100% - 19:00 | X1317: A | Y1317: BGP501 | Z1317: 2024-03-01 | AA1317: 2044-03-01 | AB1317: 0 | AE1317: AL 6 NEDAL V.061PT03.6E.000 | AF1317: 2024-03-01 | AG1317: 2054-03-01 | AI1317: AU.6.6.200.00.0 | AJ1317: 2024-03-01 | AK1317: 2054-03-01 | AL1317: {"coordinates":[5.418950983069389,51.47165850753126],"type":"Point"} | AM1317: 51.47165850753126, 5.418950983069389 | AN1317: 51.47165883012373, 5.418952500402805 | AO1317: LED6-4S/830 DM11 | AP1317: 3000 | AQ1317: =IF(ISBLANK(AP1317), IFERROR(IF(VLOOKUP(AO1317, Ellens_additions!$A$2:$B$252, 2, FALSE) = "", "", VLOOKUP(AO1317, Ellens_additions!$A$2:$B$252, 2, FALSE)), 0), AP1317) -> 3000
A1319: Achtseweg Noord 228 | B1319: 4938507 | C1319: 6 Strijp | D1319: 62 Halve Maan | E1319: 628 Mispelhoef | F1319: Achtseweg Noord | H1319: 228 | J1319: Gemeente Eindhoven | K1319: 157149.94 | L1319: 387028.45 | N1319: LED6-4S/830 DM11 | O1319: 2024-03-01 | P1319: 2049-04-18 | S1319: 6.9 | T1319: 600 | V1319: LED | W1319: in30lux 100% - 19:00 | X1319: A | Y1319: BGP501 | Z1319: 2024-03-01 | AA1319: 2044-03-01 | AB1319: 0 | AE1319: AL 6 NEDAL V.061PT03.6E.000 | AF1319: 2024-03-01 | AG1319: 2054-03-01 | AI1319: AU.6.6.200.00.0 | AJ1319: 2024-03-01 | AK1319: 2054-03-01 | AL1319: {"coordinates":[5.418143305439656,51.4723093430723],"type":"Point"} | AM1319: 51.4723093430723, 5.418143305439656 | AN1319: 51.47230966521785, 5.418144825830935 | AO1319: LED6-4S/830 DM11 | AP1319: 3000 | AQ1319: =IF(ISBLANK(AP1319), IFERROR(IF(VLOOKUP(AO1319, Ellens_additions!$A$2:$B$252, 2, FALSE) = "", "", VLOOKUP(AO1319, Ellens_additions!$A$2:$B$252, 2, FALSE)), 0), AP1319) -> 3000
A1321: Achtseweg Noord 229 | B1321: 4938508 | C1321: 6 Strijp | D1321: 62 Halve Maan | E1321: 628 Mispelhoef | F1321: Achtseweg Noord | H1321: 229 | J1321: Gemeente Eindhoven | K1321: 157126.77 | L1321: 387052.23 | N1321: LED6-4S/830 DM11 | O1321: 2024-03-01 | P1321: 2049-04-18 | S1321: 6.9 | T1321: 600 | V1321: LED | W1321: in30lux 100% - 19:00 | X1321: A | Y1321: BGP501 | Z1321: 2024-03-01 | AA1321: 2044-03-01 | AB1321: 0 | AE1321: AL 6 NEDAL V.061PT03.6E.000 | AF1321: 2024-03-01 | AG1321: 2054-03-01 | AI1321: AU.6.6.200.00.0 | AJ1321: 2024-03-01 | AK1321: 2054-03-01 | AL1321: {"coordinates":[5.417809980588557,51.47252317296097],"type":"Point"} | AM1321: 51.47252317296097, 5.417809980588557 | AN1321: 51.47252349486888, 5.417811501981995 | AO1321: LED6-4S/830 DM11 | AP1321: 3000 | AQ1321: =IF(ISBLANK(AP1321), IFERROR(IF(VLOOKUP(AO1321, Ellens_additions!$A$2:$B$252, 2, FALSE) = "", "", VLOOKUP(AO1321, Ellens_additions!$A$2:$B$252, 2, FALSE)), 0), AP1321) -> 3000
A1323: Achtseweg Noord 231 | B1323: 4938509 | C1323: 6 Strijp | D1323: 62 Halve Maan | E1323: 628 Mispelhoef | F1323: Achtseweg Noord | H1323: 231 | J1323: Gemeente Eindhoven | K1323: 157106.58 | L1323: 387076.77 | N1323: LED6-4S/830 DM11 | O1323: 2024-03-01 | P1323: 2049-04-18 | S1323: 6.9 | T1323: 600 | V1323: LED | W1323: in30lux 100% - 19:00 | X1323: A | Y1323: BGP501 | Z1323: 2024-03-01 | AA1323: 2044-03-01 | AB1323: 0 | AE1323: AL 6 NEDAL V.061PT03.6E.000 | AF1323: 2024-03-01 | AG1323: 2054-03-01 | AI1323: AU.6.6.200.00.0 | AJ1323: 2024-03-01 | AK1323: 2054-03-01 | AL1323: {"coordinates":[5.417519476357645,51.47274384002374],"type":"Point"} | AM1323: 51.47274384002374, 5.417519476357645 | AN1323: 51.47274416174568, 5.417520998770554 | AO1323: LED6-4S/830 DM11 | AP1323: 3000 | AQ1323: =IF(ISBLANK(AP1323), IFERROR(IF(VLOOKUP(AO1323, Ellens_additions!$A$2:$B$252, 2, FALSE) = "", "", VLOOKUP(AO1323, Ellens_additions!$A$2:$B$252, 2, FALSE)), 0), AP1323) -> 3000
A2012: Nuenenseweg 001 | B2012: 4946635 | C2012: 4 Woensel-Zuid | D2012: 43 Begijnenbroek | E2012: 436 Eckartdal | F2012: Nuenenseweg | H2012: 001 | J2012: Gemeente Eindhoven | K2012: 162916.67 | L2012: 386221.09 | M2012: 1 | N2012: LED35/830 DM70 | O2012: 2023-12-01 | P2012: 2049-11-09 | Q2012: led | S2012: 28 | T2012: 3400 | V2012: LED | W2012: in30lux 100% - 19:00 | X2012: A | Y2012: BGP760 | Z2012: 2023-12-01 | AA2012: 2048-12-01 | AB2012: 0 | AE2012: AL 6 NEDAL V.061PT03.6E.000 | AF2012: 2023-12-01 | AG2012: 2053-12-01 | AI2012: AL 0,20 Nedal AU.6.6 | AJ2012: 2023-12-01 | AK2012: 2053-12-01 | AL2012: {"coordinates":[5.501125088344949,51.465000598910564],"type":"Point"} | AM2012: 51.465000598910564, 5.501125088344949 | AN2012: 51.4650009606955, 5.501126329724579 | AO2012: LED35/830 DM70 | AP2012: 3000 | AQ2012: =IF(ISBLANK(AP2012), IFERROR(IF(VLOOKUP(AO2012, Ellens_additions!$A$2:$B$252, 2, FALSE) = "", "", VLOOKUP(AO2012, Ellens_additions!$A$2:$B$252, 2, FALSE)), 0), AP2012) -> 3000
A2523: 't Hofke 014 | B2523: 4940180 | C2523: 3 Tongelre | D2523: 33 Oud-Tongelre | E2523: 335 't Hofke | F2523: 't Hofke | H2523: 014 | J2523: Gemeente Eindhoven | K2523: 164103.67 | L2523: 384483.1 | M2523: 1 | N2523: LED50/830 DM70 | O2523: 2023-05-26 | P2523: 2048-08-02 | Q2523: led | S2523: 38 | T2523: 5000 | U2523: 80 | V2523: LED | W2523: in30lux 100% - 19:00 | X2523: A | Y2523: BGP761 | Z2523: 2023-05-26 | AA2523: 2043-05-26 | AB2523: 0 | AE2523: AL 6 NEDAL V.061PT03.6E.000 | AF2523: 2023-05-26 | AG2523: 2053-05-26 | AI2523: AL ENKEL 1M UE6.1000 | AJ2523: 2023-05-26 | AK2523: 2043-05-26 | AL2523: {"coordinates":[5.518161822875493,51.44936051020596],"type":"Point"} | AM2523: 51.44936051020596, 5.518161822875493 | AN2523: 51.44936085823947, 5.518162908468947 | AO2523: LED50/830 DM70 | AP2523: 3000 | AQ2523: =IF(ISBLANK(AP2523), IFERROR(IF(VLOOKUP(AO2523, Ellens_additions!$A$2:$B$252, 2, FALSE) = "", "", VLOOKUP(AO2523, Ellens_additions!$A$2:$B$252, 2, FALSE)), 0), AP2523) -> 3000
A2525: 't Hofke 017 | B2525: 4940183 | C2525: 3 Tongelre | D2525: 33 Oud-Tongelre | E2525: 335 't Hofke | F2525: 't Hofke | H2525: 017 | J2525: Gemeente Eindhoven | K2525: 164167.34 | L2525: 384509.47 | M2525: 1 | N2525: LED50/830 DM70 | O2525: 2023-05-26 | P2525: 2048-08-02 | Q2525: led | S2525: 38 | T2525: 5000 | U2525: 80 | V2525: LED | W2525: in30lux 100% - 19:00 | X2525: A | Y2525: BGP761 | Z2525: 2023-05-26 | AA2525: 2043-05-26 | AB2525: 0 | AE2525: AL 6 NEDAL V.061PT03.6E.000 | AF2525: 2023-05-26 | AG2525: 2053-05-26 | AI2525: AL ENKEL 1M UE6.1000 | AJ2525: 2023-05-26 | AK2525: 2043-05-26 | AL2525: {"coordinates":[5.519078492956425,51.44959650993298],"type":"Point"} | AM2525: 51.44959650993298, 5.519078492956425 | AN2525: 51.44959685866539, 5.519079576194202 | AO2525: LED50/830 DM70 | AP2525: 3000 | AQ2525: =IF(ISBLANK(AP2525), IFERROR(IF(VLOOKUP(AO2525, Ellens_additions!$A$2:$B$252, 2, FALSE) = "", "", VLOOKUP(AO2525, Ellens_additions!$A$2:$B$252, 2, FALSE)), 0), AP2525) -> 3000
A2527: 't Hofke 019 | B2527: 4940185 | C2527: 3 Tongelre | D2527: 33 Oud-Tongelre | E2527: 335 't Hofke | F2527: 't Hofke | H2527: 019 | J2527: Gemeente Eindhoven | K2527: 164225.03 | L2527: 384519.48 | M2527: 1 | N2527: LED50/830 DM70 | O2527: 2023-05-26 | P2527: 2048-08-02 | Q2527: led | S2527: 38 | T2527: 5000 | U2527: 80 | V2527: LED | W2527: in30lux 100% - 19:00 | X2527: A | Y2527: BGP761 | Z2527: 2023-05-26 | AA2527: 2043-05-26 | AB2527: 0 | AE2527: AL 6 NEDAL V.061PT03.6E.000 | AF2527: 2023-05-26 | AG2527: 2053-05-26 | AI2527: AL ENKEL 1M UE6.1000 | AJ2527: 2023-05-26 | AK2527: 2043-05-26 | AL2527: {"coordinates":[5.519908664002442,51.449685510463304],"type":"Point"} | AM2527: 51.449685510463304, 5.519908664002442 | AN2527: 51.44968585965822, 5.5199097444402385 | AO2527: LED50/830 DM70 | AP2527: 3000 | AQ2527: =IF(ISBLANK(AP2527), IFERROR(IF(VLOOKUP(AO2527, Ellens_additions!$A$2:$B$252, 2, FALSE) = "", "", VLOOKUP(AO2527, Ellens_additions!$A$2:$B$252, 2, FALSE)), 0), AP2527) -> 3000
A2529: 't Hofke 021 | B2529: 4940186 | C2529: 3 Tongelre | D2529: 33 Oud-Tongelre | E2529: 335 't Hofke | F2529: 't Hofke | H2529: 021 | J2529: Gemeente Eindhoven | K2529: 164257.99 | L2529: 384513.48 | M2529: 1 | N2529: LED50/830 DM70 | O2529: 2023-05-26 | P2529: 2048-08-02 | Q2529: led | S2529: 38 | T2529: 5000 | U2529: 80 | V2529: LED | W2529: in30lux 100% - 19:00 | X2529: A | Y2529: BGP761 | Z2529: 2023-05-26 | AA2529: 2043-05-26 | AB2529: 0 | AE2529: AL 6 NEDAL V.061PT03.6E.000 | AF2529: 2023-05-26 | AG2529: 2053-05-26 | AI2529: AL ENKEL 1M UE6.1000 | AJ2529: 2023-05-26 | AK2529: 2043-05-26 | AL2529: {"coordinates":[5.5203826633835975,51.44963101053202],"type":"Point"} | AM2529: 51.44963101053202, 5.5203826633835975 | AN2529: 51.44963135985511, 5.5203837416609 | AO2529: LED50/830 DM70 | AP2529: 3000 | AQ2529: =IF(ISBLANK(AP2529), IFERROR(IF(VLOOKUP(AO2529, Ellens_additions!$A$2:$B$252, 2, FALSE) = "", "", VLOOKUP(AO2529, Ellens_additions!$A$2:$B$252, 2, FALSE)), 0), AP2529) -> 3000
A2531: Loostraat 002 | B2531: 4940190 | C2531: 3 Tongelre | D2531: 33 Oud-Tongelre | E2531: 335 't Hofke | F2531: Loostraat | H2531: 002 | J2531: Gemeente Eindhoven | K2531: 164371.18 | L2531: 384551.23 | N2531: Siteco SL 21 iQ mini | O2531: 2023-07-27 | P2531: 2049-06-10 | Q2531: led | S2531: 12 | T2531: 3724 | U2531: 70 | V2531: LED | W2531: In 30lux 10% - bij b | Y2531: Siteco Streetlight S | Z2531: 2023-07-27 | AA2531: 2048-07-27 | AB2531: 0 | AE2531: ST 5 VDL CCOL 5.0 PTU60-GST133-60-DCC | AF2531: 2023-07-27 | AG2531: 2063-07-27 | AI2531: SL21 mast flange ops | AJ2531: 2023-07-27 | AK2531: 2048-07-27 | AL2531: {"coordinates":[5.522011899939438,51.4499685199002],"type":"Point"} | AM2531: 51.4499685199002, 5.522011899939438 | AN2531: 51.44996887032349, 5.522012973587275 | AO2531: Siteco SL 21 iQ mini | AQ2531: =IF(ISBLANK(AP2531), IFERROR(IF(VLOOKUP(AO2531, Ellens_additions!$A$2:$B$252, 2, FALSE) = "", "", VLOOKUP(AO2531, Ellens_additions!$A$2:$B$252, 2, FALSE)), 0), AP2531) -> 0
A2533: Loostraat 003 | B2533: 4940191 | C2533: 3 Tongelre | D2533: 33 Oud-Tongelre | E2533: 335 't Hofke | F2533: Loostraat | H2533: 003 | J2533: Gemeente Eindhoven | K2533: 164389.47 | L2533: 384562.54 | N2533: Siteco SL 21 iQ mini | O2533: 2023-07-27 | P2533: 2049-06-10 | Q2533: led | S2533: 12 | T2533: 3724 | U2533: 70 | V2533: LED | W2533: In 30lux 10% - bij b | Y2533: Siteco Streetlight S | Z2533: 2023-07-27 | AA2533: 2048-07-27 | AB2533: 0 | AE2533: ST 5 VDL CCOL 5.0 PTU60-GST133-60-DCC | AF2533: 2023-07-27 | AG2533: 2063-07-27 | AI2533: SL21 mast flange ops | AJ2533: 2023-07-27 | AK2533: 2048-07-27 | AL2533: {"coordinates":[5.522275279229896,51.45006985959181],"type":"Point"} | AM2533: 51.45006985959181, 5.522275279229896 | AN2533: 51.45007021024766, 5.522276352378084 | AO2533: Siteco SL 21 iQ mini | AQ2533: =IF(ISBLANK(AP2533), IFERROR(IF(VLOOKUP(AO2533, Ellens_additions!$A$2:$B$252, 2, FALSE) = "", "", VLOOKUP(AO2533, Ellens_additions!$A$2:$B$252, 2, FALSE)), 0), AP2533) -> 0
A2535: Loostraat 004 | B2535: 4940192 | C2535: 3 Tongelre | D2535: 33 Oud-Tongelre | E2535: 335 't Hofke | F2535: Loostraat | H2535: 004 | J2535: Gemeente Eindhoven | K2535: 164415.73 | L2535: 384561.86 | N2535: Siteco SL 21 iQ mini | O2535: 2023-07-27 | P2535: 2049-06-10 | Q2535: led | S2535: 12 | T2535: 3724 | U2535: 70 | V2535: LED | W2535: In 30lux 10% - bij b | Y2535: Siteco Streetlight S | Z2535: 2023-07-27 | AA2535: 2048-07-27 | AB2535: 0 | AE2535: ST 5 VDL CCOL 5.0 PTU60-GST133-60-DCC | AF2535: 2023-07-27 | AG2535: 2063-07-27 | AI2535: SL21 mast flange ops | AJ2535: 2023-07-27 | AK2535: 2048-07-27 | AL2535: {"coordinates":[5.522653049607383,51.45006326911672],"type":"Point"} | AM2535: 51.45006326911672, 5.522653049607383 | AN2535: 51.450063619919284, 5.522654121229628 | AO2535: Siteco SL 21 iQ mini | AQ2535: =IF(ISBLANK(AP2535), IFERROR(IF(VLOOKUP(AO2535, Ellens_additions!$A$2:$B$252, 2, FALSE) = "", "", VLOOKUP(AO2535, Ellens_additions!$A$2:$B$252, 2, FALSE)), 0), AP2535) -> 0
A2537: Loostraat 033 | B2537: 4940195 | C2537: 3 Tongelre | D2537: 33 Oud-Tongelre | E2537: 335 't Hofke | F2537: Loostraat | H2537: 033 | J2537: Gemeente Eindhoven | K2537: 164997.42 | L2537: 384505.23 | N2537: Siteco SL 21 iQ mini | O2537: 2023-07-07 | P2537: 2049-05-19 | Q2537: led | S2537: 12 | T2537: 3724 | U2537: 70 | V2537: LED | W2537: In 30lux 10% - bij b | Y2537: Siteco Streetlight S | Z2537: 2023-07-07 | AA2537: 2048-07-07 | AB2537: 0 | AE2537: ST 5 VDL CCOL 5.0 PTU60-GST133-60-DCC | AF2537: 2023-07-07 | AG2537: 2063-07-07 | AI2537: SL21 mast flange ops | AJ2537: 2023-07-07 | AK2537: 2048-07-07 | AL2537: {"coordinates":[5.5310196447370945,51.44954421034897],"type":"Point"} | AM2537: 51.44954421034897, 5.5310196447370945 | AN2537: 51.44954456357334, 5.531020682201073 | AO2537: Siteco SL 21 iQ mini | AQ2537: =IF(ISBLANK(AP2537), IFERROR(IF(VLOOKUP(AO2537, Ellens_additions!$A$2:$B$252, 2, FALSE) = "", "", VLOOKUP(AO2537, Ellens_additions!$A$2:$B$252, 2, FALSE)), 0), AP2537) -> 0
A2539: Loostraat 034 | B2539: 4940196 | C2539: 3 Tongelre | D2539: 33 Oud-Tongelre | E2539: 335 't Hofke | F2539: Loostraat | H2539: 034 | J2539: Gemeente Eindhoven | K2539: 165024.23 | L2539: 384485.79 | N2539: Siteco SL 21 iQ mini | O2539: 2023-07-07 | P2539: 2049-05-19 | Q2539: led | S2539: 12 | T2539: 3724 | U2539: 70 | V2539: LED | W2539: In 30lux 10% - bij b | Y2539: Siteco Streetlight S | Z2539: 2023-07-07 | AA2539: 2048-07-07 | AB2539: 0 | AE2539: ST 5 VDL CCOL 5.0 PTU60-GST133-60-DCC | AF2539: 2023-07-07 | AG2539: 2063-07-07 | AI2539: SL21 mast flange ops | AJ2539: 2023-07-07 | AK2539: 2048-07-07 | AL2539: {"coordinates":[5.53140470469562,51.449369019801765],"type":"Point"} | AM2539: 51.449369019801765, 5.53140470469562 | AN2539: 51.449369372938364, 5.53140573984706 | AO2539: Siteco SL 21 iQ mini | AQ2539: =IF(ISBLANK(AP2539), IFERROR(IF(VLOOKUP(AO2539, Ellens_additions!$A$2:$B$252, 2, FALSE) = "", "", VLOOKUP(AO2539, Ellens_additions!$A$2:$B$252, 2, FALSE)), 0), AP2539) -> 0
A2541: Loostraat 035 | B2541: 4940199 | C2541: 3 Tongelre | D2541: 33 Oud-Tongelre | E2541: 335 't Hofke | F2541: Loostraat | H2541: 035 | J2541: Gemeente Eindhoven | K2541: 165044.3 | L2541: 384467.27 | N2541: Siteco SL 21 iQ mini | O2541: 2023-07-07 | P2541: 2049-05-19 | Q2541: led | S2541: 12 | T2541: 3724 | U2541: 70 | V2541: LED | W2541: In 30lux 10% - bij b | Y2541: Siteco Streetlight S | Z2541: 2023-07-07 | AA2541: 2048-07-07 | AB2541: 0 | AE2541: ST 5 VDL CCOL 5.0 PTU60-GST133-60-DCC | AF2541: 2023-07-07 | AG2541: 2063-07-07 | AI2541: SL21 mast flange ops | AJ2541: 2023-07-07 | AK2541: 2048-07-07 | AL2541: {"coordinates":[5.531692865029015,51.44920220967948],"type":"Point"} | AM2541: 51.44920220967948, 5.531692865029015 | AN2541: 51.44920256270343, 5.531693898272117 | AO2541: Siteco SL 21 iQ mini | AQ2541: =IF(ISBLANK(AP2541), IFERROR(IF(VLOOKUP(AO2541, Ellens_additions!$A$2:$B$252, 2, FALSE) = "", "", VLOOKUP(AO2541, Ellens_additions!$A$2:$B$252, 2, FALSE)), 0), AP2541) -> 0
A2543: Loostraat 012 | B2543: 4940203 | C2543: 3 Tongelre | D2543: 33 Oud-Tongelre | E2543: 335 't Hofke | F2543: Loostraat | H2543: 012 | J2543: Gemeente Eindhoven | K2543: 164492.31 | L2543: 384586.48 | N2543: Siteco SL 21 iQ mini | O2543: 2023-07-27 | P2543: 2049-06-10 | Q2543: led | S2543: 12 | T2543: 3724 | U2543: 70 | V2543: LED | W2543: In 30lux 10% - bij b | X2543: B | Y2543: Siteco Streetlight S | Z2543: 2023-07-27 | AA2543: 2048-07-27 | AB2543: 0 | AI2543: SL21 mast flange ops | AJ2543: 2023-07-27 | AK2543: 2048-07-27 | AL2543: {"coordinates":[5.5237554697858835,51.450283279573995],"type":"Point"} | AM2543: 51.450283279573995, 5.5237554697858835 | AN2543: 51.450283631089654, 5.5237565382279294 | AO2543: Siteco SL 21 iQ mini | AQ2543: =IF(ISBLANK(AP2543), IFERROR(IF(VLOOKUP(AO2543, Ellens_additions!$A$2:$B$252, 2, FALSE) = "", "", VLOOKUP(AO2543, Ellens_additions!$A$2:$B$252, 2, FALSE)), 0), AP2543) -> 0
A2545: Loostraat 019 | B2545: 4940212 | C2545: 3 Tongelre | D2545: 33 Oud-Tongelre | E2545: 335 't Hofke | F2545: Loostraat | H2545: 019 | J2545: Gemeente Eindhoven | K2545: 164674.32 | L2545: 384617.42 | N2545: Siteco SL 21 iQ mini | O2545: 2023-04-21 | P2545: 2049-03-19 | Q2545: led | S2545: 12 | T2545: 3724 | U2545: 70 | V2545: LED | W2545: In 30lux 10% - bij b | Y2545: Siteco Streetlight S | Z2545: 2023-04-21 | AA2545: 2048-04-21 | AB2545: 0 | AE2545: ST 5 VDL CCOL 5.0 PTU60-GST133-60-DCC | AF2545: 2023-04-21 | AG2545: 2063-04-21 | AI2545: SL21 mast flange ops | AJ2545: 2023-04-21 | AK2545: 2048-04-21 | AL2545: {"coordinates":[5.526374670487558,51.4505583291657],"type":"Point"} | AM2545: 51.4505583291657, 5.526374670487558 | AN2545: 51.45055868198091, 5.526375730447872 | AO2545: Siteco SL 21 iQ mini | AQ2545: =IF(ISBLANK(AP2545), IFERROR(IF(VLOOKUP(AO2545, Ellens_additions!$A$2:$B$252, 2, FALSE) = "", "", VLOOKUP(AO2545, Ellens_additions!$A$2:$B$252, 2, FALSE)), 0), AP2545) -> 0
...

Sheet algoritme tabel 
A1: color temp | D1: 1800 | E1: 2200 | F1: 2000 | G1: 2700 | H1: 3000 | I1: 4000 | J1: > 4000
C2: NATURE | D2: 5 | E2: 5 | F2: 5 | G2: 4 | H2: 3 | I2: 2 | J2: 1
C3: HUMANS | D3: 2 | E3: 2 | F3: 2 | G3: 3 | H3: 3 | I3: 4 | J3: 5
C4: EFFICIENCY | D4: 4 | E4: 4.333333 | F4: 4.333333 | G4: 4.333333 | H4: 4 | I4: 3.333333 | J4: 2.333333
A6: pole_height | D6: < 1 | E6: < 2 | F6: < 4.2 | G6: < 6 | H6: < 10 | I6: > 10
C7: NATURE | D7: 5 | E7: 5 | F7: 4 | G7: 3 | H7: 2 | I7: 1
C8: HUMANS | D8: 1 | E8: 2 | F8: 3 | G8: 3 | H8: 4 | I8: 5
C9: EFFICIENCY | D9: 3 | E9: 3 | F9: 2.333333 | G9: 2 | H9: 2.333333 | I9: 2.666667
A11: lumen | D11: 1 | E11: 5 | F11: 10 | G11: 20 | H11: 50 | I11: > 50
C12: NATURE | D12: 5 | E12: 4 | F12: 3 | G12: 2 | H12: 1 | I12: 1
C13: HUMANS | D13: 0 | E13: 0 | F13: 0 | G13: 0 | H13: 0 | I13: 0
C14: EFFICIENCY | D14: 0 | E14: 0 | F14: 0 | G14: 0 | H14: 0 | I14: 0

Sheet Cat_helper_table

Sheet Ellens_additions
A1: TYPE_LAMP (Alles zonder kleur temperatuur of 1000 K?) | B1: Kleurtemperatuur
A2: SON-T PIA PLUS 50W | B2: 2000
A3: SON PIA PLUS 100W | B3: 2000
A4: SOX PSG 55W | B4: 1800
A5: PLL 36 W xtra polar
A6: SON-T PIA PLUS 70W | B6: 2000
A7: SON-T 70W | B7: 2000
A8: 16 LED 19W 350mA (Pi
A9: Unique-L Cool 36 Wat
A10: SON PIA PLUS 150W | B10: 2000
A11: SON PIA PLUS 70W I | B11: 2000
A12: 96 LED type II short
A13: SILL 153 LED Blauw 1
A14: 120 LED type II shor
A15: LED upgrade KIT Blue
A16: HRIT 250BL
A17: CDO-TT Plus 150W | B17: 2800
A18: CDM-T 150W
A19: SON-T PIA PLUS 150W | B19: 2000
A20: CDM-T 35W
A21: SON-T 150W | B21: 2000
A22: Saled Led PS-L 26W 4
A23: PLL 55 W | B23: 3000
A24: CDO-ET Plus 100W | B24: 2800
A25: SON-T PIA PLUS 100W | B25: 2000
A26: CPO-TW 60W Xtra | B26: 2800
A27: CPO-TW 140W | B27: 2800
A28: PLL 55 W xtra polar | B28: 3000
A29: Unique-L Cool 55 Wat
A30: 28 LED 45W 5150 Lume
A31: CPO-T 60W | B31: 2800
A32: CPO-TW 90W Xtra | B32: 2800
A33: CPO-T 90W | B33: 2800
A34: HCI-T 35 W
A35: 24 LED LENSOFLEX2 27
A36: 72 LED LENSOFLEX2 78
A37: Golden Green 24W 250 | B37: 3000 | C37: hier moet zwaailicht op. Groenaandeel in kleurtemperatuur is te hoog
A38: 56 LED 63W 350mA 780
A39: Fortimo LED LLM 4500 | B39: 3000
A40: SCHREDER TECEO 5118
...
